Workbook
Name SegmentaciónDeDatos_country: #N/A
Name SegmentaciónDeDatos_Icono: #N/A
Name SegmentaciónDeDatos_sector: #N/A
Name Slicer_Continente: #N/A
Name Slicer_repayment_interval: #N/A

Sheet Sheet2
A1: Row Labels | B1: Sum of loan_amount | D1: Row Labels | E1: Sum of funded_amount | G1: Row Labels | H1: Sum of paid_amount | J1: Row Labels | K1: Sum of loan_amount | M1: Row Labels | N1: Sum of funded_amount
A2: Agriculture | B2: 1907300 | D2: Agriculture | E2: 1845825 | G2: Agriculture | H2: 61475 | J2: Albania | K2: 64800 | M2: Africa | N2: 1906075
A3: Arts | B3: 208350 | D3: Arts | E3: 200960 | G3: Arts | H3: 7390 | J3: Armenia | K3: 175500 | M3: Asia | N3: 2293950
A4: Clothing | B4: 647175 | D4: Clothing | E4: 624755 | G4: Clothing | H4: 22420 | J4: Azerbaijan | K4: 94950 | M4: Central America | N4: 1133000
A5: Construction | B5: 131375 | D5: Construction | E5: 130475 | G5: Construction | H5: 900 | J5: Bolivia | K5: 321175 | M5: North America | N5: 368195
A6: Education | B6: 405850 | D6: Education | E6: 405850 | G6: Education | H6: 0 | J6: Brazil | K6: 1700 | M6: Oceania | N6: 120825
A7: Entertainment | B7: 16675 | D7: Entertainment | E7: 16675 | G7: Entertainment | H7: 0 | J7: Burkina Faso | K7: 22875 | M7: Rest of Europe | N7: 1024275
A8: Food | B8: 2119425 | D8: Food | E8: 2062025 | G8: Food | H8: 57400 | J8: Burundi | K8: 129400 | M8: South America | N8: 2029575
A9: Health | B9: 75200 | D9: Health | E9: 75200 | G9: Health | H9: 0 | J9: Cambodia | K9: 300875 | M9: Grand Total | N9: 8875895
A10: Housing | B10: 479675 | D10: Housing | E10: 446775 | G10: Housing | H10: 32900 | J10: Cameroon | K10: 21125
A11: Manufacturing | B11: 116275 | D11: Manufacturing | E11: 116275 | G11: Manufacturing | H11: 0 | J11: Chile | K11: 18475
A12: Personal Use | B12: 170050 | D12: Personal Use | E12: 162375 | G12: Personal Use | H12: 7675 | J12: Colombia | K12: 280150
A13: Retail | B13: 1773500 | D13: Retail | E13: 1712465 | G13: Retail | H13: 61035 | J13: Congo | K13: 34800
A14: Services | B14: 826475 | D14: Services | E14: 796465 | G14: Services | H14: 30010 | J14: Costa Rica | K14: 35050
A15: Transportation | B15: 307750 | D15: Transportation | E15: 269175 | G15: Transportation | H15: 38575 | J15: Dominican Republic | K15: 31650
A16: Wholesale | B16: 10925 | D16: Wholesale | E16: 10600 | G16: Wholesale | H16: 325 | J16: Ecuador | K16: 351300
A17: Grand Total | B17: 9196000 | D17: Grand Total | E17: 8875895 | G17: Grand Total | H17: 320105 | J17: El Salvador | K17: 601300
J18: Georgia | K18: 238825
J19: Ghana | K19: 42600
J20: Guatemala | K20: 58975
J21: Haiti | K21: 57850
J22: Honduras | K22: 119600
D23: Row Labels | E23: Sum of funded_amount | J23: India | K23: 184975 | M23: Row Labels | N23: Sum of funded_amount
D24: female | E24: 6434015 | J24: Indonesia | K24: 50025 | M24: bullet | N24: 548120
D25: male | E25: 2441880 | J25: Iraq | K25: 97800 | M25: irregular | N25: 2737575
D26: Grand Total | E26: 8875895 | J26: Israel | K26: 20375 | M26: monthly | N26: 5588700
J27: Jordan | K27: 133775 | M27: weekly | N27: 1500
J28: Kenya | K28: 418400 | M28: Grand Total | N28: 8875895
J29: Kosovo | K29: 23925
J30: Kyrgyzstan | K30: 106575
J31: Lebanon | K31: 25625
J32: Liberia | K32: 83900
J33: Mali | K33: 101625
J34: Mexico | K34: 55125
J35: Mongolia | K35: 141650
J36: Nepal | K36: 5100
J37: Nicaragua | K37: 242825
J38: Pakistan | K38: 207100
J39: Palestine | K39: 312250
J40: Paraguay | K40: 586400
...

Sheet kiva_loans (muestra)
A1: id | B1: funded_amount | C1: loan_amount | D1: activity | E1: sector | F1: use | G1: country_code | H1: country | I1: region | J1: currency | K1: partner_id | L1: posted_time | M1: disbursed_time | N1: funded_time | O1: term_in_months | P1: lender_count | Q1: borrower_genders | R1: repayment_interval | S1: date | T1: Nivel de Credito | U1: Continente | V1: Icono
A2: 654167 | B2: 2450 | C2: 2450 | D2: Livestock | E2: Agriculture | F2: to buy a dairy cow | G2: AL | H2: Albania | I2: Korce | J2: ALL | K2: 2390 | L2: 41645.479 | M2: 41631.333 | N2: 41653.64 | O2: 38 | P2: 94 | Q2: female | R2: monthly | S2: 41645 | T2: =IF(kiva_loans__muestra[[#This Row],[loan_amount]]>5000,"Alto","Bajo") -> Bajo | U2: =VLOOKUP(kiva_loans__muestra[[#This Row],[country]],Pais!A:B,2,FALSE) -> Rest of Europe | V2: 👩 F
A3: 655765 | B3: 2425 | C3: 2425 | D3: Dairy | E3: Agriculture | F3: to buy a dairy cow | G3: AL | H3: Albania | I3: Elbasan | J3: ALL | K3: 2390 | L3: 41648.565 | M3: 41621.333 | N3: 41659.048 | O3: 32 | P3: 93 | Q3: male | R3: monthly | S3: 41648 | T3: =IF(kiva_loans__muestra[[#This Row],[loan_amount]]>5000,"Alto","Bajo") -> Bajo | U3: =VLOOKUP(kiva_loans__muestra[[#This Row],[country]],Pais!A:B,2,FALSE) -> Rest of Europe | V3: 👨‍🦰M
A4: 655779 | B4: 975 | C4: 975 | D4: Livestock | E4: Agriculture | F4: to buy fodder for her animals | G4: AL | H4: Albania | I4: Korce | J4: ALL | K4: 2390 | L4: 41648.603 | M4: 41638.333 | N4: 41652.081 | O4: 21 | P4: 26 | Q4: female | R4: monthly | S4: 41648 | T4: =IF(kiva_loans__muestra[[#This Row],[loan_amount]]>5000,"Alto","Bajo") -> Bajo | U4: =VLOOKUP(kiva_loans__muestra[[#This Row],[country]],Pais!A:B,2,FALSE) -> Rest of Europe | V4: 👩 F
A5: 656172 | B5: 975 | C5: 975 | D5: Livestock | E5: Agriculture | F5: to buy baby goats. | G5: AL | H5: Albania | I5: Elbasan | J5: ALL | K5: 2390 | L5: 41649.595 | M5: 41649.333 | N5: 41650.915 | O5: 20 | P5: 37 | Q5: male | R5: monthly | S5: 41649 | T5: =IF(kiva_loans__muestra[[#This Row],[loan_amount]]>5000,"Alto","Bajo") -> Bajo | U5: =VLOOKUP(kiva_loans__muestra[[#This Row],[country]],Pais!A:B,2,FALSE) -> Rest of Europe | V5: 👨‍🦰M
A6: 656175 | B6: 975 | C6: 975 | D6: Grocery Store | E6: Food | F6: To stock up on inventory items for her grocery store and also buy fodder for the animals | G6: AL | H6: Albania | J6: ALL | K6: 2390 | L6: 41649.605 | M6: 41648.333 | N6: 41652.926 | O6: 20 | P6: 31 | Q6: female | R6: monthly | S6: 41649 | T6: =IF(kiva_loans__muestra[[#This Row],[loan_amount]]>5000,"Alto","Bajo") -> Bajo | U6: =VLOOKUP(kiva_loans__muestra[[#This Row],[country]],Pais!A:B,2,FALSE) -> Rest of Europe | V6: 👩 F
A7: 656708 | B7: 1950 | C7: 1950 | D7: Used Clothing | E7: Clothing | F7: To buy used clothes to resell | G7: AL | H7: Albania | J7: ALL | K7: 2390 | L7: 41652.586 | M7: 41649.333 | N7: 41659.548 | O7: 26 | P7: 70 | Q7: male | R7: monthly | S7: 41652 | T7: =IF(kiva_loans__muestra[[#This Row],[loan_amount]]>5000,"Alto","Bajo") -> Bajo | U7: =VLOOKUP(kiva_loans__muestra[[#This Row],[country]],Pais!A:B,2,FALSE) -> Rest of Europe | V7: 👨‍🦰M
A8: 656716 | B8: 975 | C8: 975 | D8: Personal Housing Expenses | E8: Housing | F8: to repair the family house. | G8: AL | H8: Albania | I8: Elbasan | J8: ALL | K8: 2390 | L8: 41652.605 | M8: 41649.333 | N8: 41658.459 | O8: 20 | P8: 39 | Q8: female | R8: monthly | S8: 41652 | T8: =IF(kiva_loans__muestra[[#This Row],[loan_amount]]>5000,"Alto","Bajo") -> Bajo | U8: =VLOOKUP(kiva_loans__muestra[[#This Row],[country]],Pais!A:B,2,FALSE) -> Rest of Europe | V8: 👩 F
A9: 656724 | B9: 775 | C9: 775 | D9: Used Clothing | E9: Clothing | F9: to buy second-hand clothing to resell and to repair a damaged balcony of the family home | G9: AL | H9: Albania | I9: Korce | J9: ALL | K9: 2390 | L9: 41652.629 | M9: 41652.333 | N9: 41653.732 | O9: 17 | P9: 27 | Q9: male | R9: monthly | S9: 41652 | T9: =IF(kiva_loans__muestra[[#This Row],[loan_amount]]>5000,"Alto","Bajo") -> Bajo | U9: =VLOOKUP(kiva_loans__muestra[[#This Row],[country]],Pais!A:B,2,FALSE) -> Rest of Europe | V9: 👨‍🦰M
A10: 656731 | B10: 1950 | C10: 1950 | D10: Livestock | E10: Agriculture | F10: to buy a dairy cow | G10: AL | H10: Albania | I10: Lezhe | J10: ALL | K10: 2390 | L10: 41652.641 | M10: 41647.333 | N10: 41658.637 | O10: 29 | P10: 62 | Q10: female | R10: monthly | S10: 41652 | T10: =IF(kiva_loans__muestra[[#This Row],[loan_amount]]>5000,"Alto","Bajo") -> Bajo | U10: =VLOOKUP(kiva_loans__muestra[[#This Row],[country]],Pais!A:B,2,FALSE) -> Rest of Europe | V10: 👩 F
A11: 657018 | B11: 1475 | C11: 1475 | D11: Personal Housing Expenses | E11: Housing | F11: to buy a cheap bed and other furniture as they cannot handle sleeping on the cold floors any longer | G11: AL | H11: Albania | I11: Korce | J11: ALL | K11: 2390 | L11: 41653.401 | M11: 41652.333 | N11: 41653.846 | O11: 14 | P11: 35 | Q11: female | R11: monthly | S11: 41653 | T11: =IF(kiva_loans__muestra[[#This Row],[loan_amount]]>5000,"Alto","Bajo") -> Bajo | U11: =VLOOKUP(kiva_loans__muestra[[#This Row],[country]],Pais!A:B,2,FALSE) -> Rest of Europe | V11: 👩 F
A12: 657977 | B12: 975 | C12: 975 | D12: Higher education costs | E12: Education | F12: To pay her son's last college tuition fees. | G12: AL | H12: Albania | J12: ALL | K12: 2390 | L12: 41655.427 | M12: 41654.333 | N12: 41656.574 | O12: 14 | P12: 37 | Q12: female | R12: monthly | S12: 41655 | T12: =IF(kiva_loans__muestra[[#This Row],[loan_amount]]>5000,"Alto","Bajo") -> Bajo | U12: =VLOOKUP(kiva_loans__muestra[[#This Row],[country]],Pais!A:B,2,FALSE) -> Rest of Europe | V12: 👩 F
A13: 658089 | B13: 975 | C13: 975 | D13: Personal Housing Expenses | E13: Housing | F13: to repair his family home. | G13: AL | H13: Albania | J13: ALL | K13: 2390 | L13: 41655.609 | M13: 41654.333 | N13: 41658.624 | O13: 20 | P13: 39 | Q13: male | R13: monthly | S13: 41655 | T13: =IF(kiva_loans__muestra[[#This Row],[loan_amount]]>5000,"Alto","Bajo") -> Bajo | U13: =VLOOKUP(kiva_loans__muestra[[#This Row],[country]],Pais!A:B,2,FALSE) -> Rest of Europe | V13: 👨‍🦰M
A14: 658562 | B14: 1475 | C14: 1475 | D14: Personal Housing Expenses | E14: Housing | F14: to finish the roofing of one room | G14: AL | H14: Albania | J14: ALL | K14: 2390 | L14: 41656.459 | M14: 41655.333 | N14: 41668.758 | O14: 20 | P14: 49 | Q14: female | R14: monthly | S14: 41656 | T14: =IF(kiva_loans__muestra[[#This Row],[loan_amount]]>5000,"Alto","Bajo") -> Bajo | U14: =VLOOKUP(kiva_loans__muestra[[#This Row],[country]],Pais!A:B,2,FALSE) -> Rest of Europe | V14: 👩 F
A15: 658570 | B15: 1950 | C15: 1950 | D15: Personal Housing Expenses | E15: Housing | F15: to do some work on the family home; the little kids have been feeling very cold this winter | G15: AL | H15: Albania | I15: Korce | J15: ALL | K15: 2390 | L15: 41656.471 | M15: 41655.333 | N15: 41659.74 | O15: 22 | P15: 71 | Q15: female | R15: monthly | S15: 41656 | T15: =IF(kiva_loans__muestra[[#This Row],[loan_amount]]>5000,"Alto","Bajo") -> Bajo | U15: =VLOOKUP(kiva_loans__muestra[[#This Row],[country]],Pais!A:B,2,FALSE) -> Rest of Europe | V15: 👩 F
A16: 659454 | B16: 975 | C16: 975 | D16: Services | E16: Services | F16: to buy equipment for his plumbing services | G16: AL | H16: Albania | I16: Korce | J16: ALL | K16: 2390 | L16: 41659.603 | M16: 41656.333 | N16: 41661.803 | O16: 20 | P16: 36 | Q16: male | R16: monthly | S16: 41659 | T16: =IF(kiva_loans__muestra[[#This Row],[loan_amount]]>5000,"Alto","Bajo") -> Bajo | U16: =VLOOKUP(kiva_loans__muestra[[#This Row],[country]],Pais!A:B,2,FALSE) -> Rest of Europe | V16: 👨‍🦰M
A17: 659457 | B17: 1450 | C17: 1450 | D17: Upholstery | E17: Services | F17: to buy fabric for custom drapery services | G17: AL | H17: Albania | I17: Korce | J17: ALL | K17: 2390 | L17: 41659.617 | M17: 41656.333 | N17: 41665.056 | O17: 14 | P17: 53 | Q17: female | R17: monthly | S17: 41659 | T17: =IF(kiva_loans__muestra[[#This Row],[loan_amount]]>5000,"Alto","Bajo") -> Bajo | U17: =VLOOKUP(kiva_loans__muestra[[#This Row],[country]],Pais!A:B,2,FALSE) -> Rest of Europe | V17: 👩 F
A18: 659840 | B18: 675 | C18: 675 | D18: Dairy | E18: Agriculture | F18: to buy a dairy cow | G18: AL | H18: Albania | I18: Lezhe | J18: ALL | K18: 2390 | L18: 41660.383 | M18: 41656.333 | N18: 41661.168 | O18: 14 | P18: 24 | Q18: female | R18: monthly | S18: 41660 | T18: =IF(kiva_loans__muestra[[#This Row],[loan_amount]]>5000,"Alto","Bajo") -> Bajo | U18: =VLOOKUP(kiva_loans__muestra[[#This Row],[country]],Pais!A:B,2,FALSE) -> Rest of Europe | V18: 👩 F
A19: 659926 | B19: 1950 | C19: 1950 | D19: Agriculture | E19: Agriculture | F19: to repair a leaking roof. | G19: AL | H19: Albania | I19: Lezhe | J19: ALL | K19: 2390 | L19: 41660.492 | M19: 41659.333 | N19: 41661.81 | O19: 27 | P19: 69 | Q19: female | R19: monthly | S19: 41660 | T19: =IF(kiva_loans__muestra[[#This Row],[loan_amount]]>5000,"Alto","Bajo") -> Bajo | U19: =VLOOKUP(kiva_loans__muestra[[#This Row],[country]],Pais!A:B,2,FALSE) -> Rest of Europe | V19: 👩 F
A20: 659934 | B20: 600 | C20: 600 | D20: Agriculture | E20: Agriculture | F20: to buy onion seeds to plant. | G20: AL | H20: Albania | I20: Korce | J20: ALL | K20: 2390 | L20: 41660.505 | M20: 41656.333 | N20: 41661.19 | O20: 13 | P20: 20 | Q20: female | R20: monthly | S20: 41660 | T20: =IF(kiva_loans__muestra[[#This Row],[loan_amount]]>5000,"Alto","Bajo") -> Bajo | U20: =VLOOKUP(kiva_loans__muestra[[#This Row],[country]],Pais!A:B,2,FALSE) -> Rest of Europe | V20: 👩 F
A21: 659972 | B21: 975 | C21: 975 | D21: Agriculture | E21: Agriculture | F21: to buy a water pump for watering the plants | G21: AL | H21: Albania | I21: Korce | J21: ALL | K21: 2390 | L21: 41660.559 | M21: 41659.333 | N21: 41662.767 | O21: 26 | P21: 34 | Q21: male | R21: monthly | S21: 41660 | T21: =IF(kiva_loans__muestra[[#This Row],[loan_amount]]>5000,"Alto","Bajo") -> Bajo | U21: =VLOOKUP(kiva_loans__muestra[[#This Row],[country]],Pais!A:B,2,FALSE) -> Rest of Europe | V21: 👨‍🦰M
A22: 659980 | B22: 775 | C22: 775 | D22: Agriculture | E22: Agriculture | F22: to pay for the agricultural land certification registration documents | G22: AL | H22: Albania | I22: Elbasan | J22: ALL | K22: 2390 | L22: 41660.568 | M22: 41656.333 | N22: 41662.74 | O22: 14 | P22: 28 | Q22: female | R22: monthly | S22: 41660 | T22: =IF(kiva_loans__muestra[[#This Row],[loan_amount]]>5000,"Alto","Bajo") -> Bajo | U22: =VLOOKUP(kiva_loans__muestra[[#This Row],[country]],Pais!A:B,2,FALSE) -> Rest of Europe | V22: 👩 F
A23: 659986 | B23: 2425 | C23: 2425 | D23: Dairy | E23: Agriculture | F23: to buy baby calves | G23: AL | H23: Albania | I23: Korce | J23: ALL | K23: 2390 | L23: 41660.577 | M23: 41660.333 | N23: 41669.025 | O23: 24 | P23: 78 | Q23: female | R23: monthly | S23: 41660 | T23: =IF(kiva_loans__muestra[[#This Row],[loan_amount]]>5000,"Alto","Bajo") -> Bajo | U23: =VLOOKUP(kiva_loans__muestra[[#This Row],[country]],Pais!A:B,2,FALSE) -> Rest of Europe | V23: 👩 F
A24: 659989 | B24: 500 | C24: 500 | D24: Construction | E24: Construction | F24: To buy construction tools for her husband who does construction work | G24: AL | H24: Albania | J24: ALL | K24: 2390 | L24: 41660.583 | M24: 41660.333 | N24: 41661.728 | O24: 14 | P24: 19 | Q24: female | R24: monthly | S24: 41660 | T24: =IF(kiva_loans__muestra[[#This Row],[loan_amount]]>5000,"Alto","Bajo") -> Bajo | U24: =VLOOKUP(kiva_loans__muestra[[#This Row],[country]],Pais!A:B,2,FALSE) -> Rest of Europe | V24: 👩 F
A25: 660454 | B25: 2425 | C25: 2425 | D25: Personal Medical Expenses | E25: Health | F25: to pay for an urgent eye operation for her husband before he goes completely blind. | G25: AL | H25: Albania | I25: Korce | J25: ALL | K25: 2390 | L25: 41661.493 | M25: 41659.333 | N25: 41661.977 | O25: 38 | P25: 77 | Q25: female | R25: monthly | S25: 41661 | T25: =IF(kiva_loans__muestra[[#This Row],[loan_amount]]>5000,"Alto","Bajo") -> Bajo | U25: =VLOOKUP(kiva_loans__muestra[[#This Row],[country]],Pais!A:B,2,FALSE) -> Rest of Europe | V25: 👩 F
A26: 660997 | B26: 2425 | C26: 2425 | D26: Agriculture | E26: Agriculture | F26: to buy red onion seeds for planting | G26: AL | H26: Albania | I26: Korce | J26: ALL | K26: 2390 | L26: 41662.514 | M26: 41661.333 | N26: 41690.548 | O26: 38 | P26: 92 | Q26: female | R26: monthly | S26: 41662 | T26: =IF(kiva_loans__muestra[[#This Row],[loan_amount]]>5000,"Alto","Bajo") -> Bajo | U26: =VLOOKUP(kiva_loans__muestra[[#This Row],[country]],Pais!A:B,2,FALSE) -> Rest of Europe | V26: 👩 F
A27: 661012 | B27: 2425 | C27: 2425 | D27: Higher education costs | E27: Education | F27: to pay for his sons' university tuition fees. | G27: AL | H27: Albania | I27: Korce | J27: ALL | K27: 2390 | L27: 41662.549 | M27: 41660.333 | N27: 41668.66 | O27: 33 | P27: 70 | Q27: male | R27: monthly | S27: 41662 | T27: =IF(kiva_loans__muestra[[#This Row],[loan_amount]]>5000,"Alto","Bajo") -> Bajo | U27: =VLOOKUP(kiva_loans__muestra[[#This Row],[country]],Pais!A:B,2,FALSE) -> Rest of Europe | V27: 👨‍🦰M
A28: 661024 | B28: 500 | C28: 500 | D28: Livestock | E28: Agriculture | F28: to add sheep to her herd of dairy cows | G28: AL | H28: Albania | I28: Korce | J28: ALL | K28: 2390 | L28: 41662.568 | M28: 41659.333 | N28: 41663.631 | O28: 13 | P28: 18 | Q28: female | R28: monthly | S28: 41662 | T28: =IF(kiva_loans__muestra[[#This Row],[loan_amount]]>5000,"Alto","Bajo") -> Bajo | U28: =VLOOKUP(kiva_loans__muestra[[#This Row],[country]],Pais!A:B,2,FALSE) -> Rest of Europe | V28: 👩 F
A29: 661032 | B29: 975 | C29: 975 | D29: Used Clothing | E29: Clothing | G29: AL | H29: Albania | J29: ALL | K29: 2390 | L29: 41662.578 | M29: 41656.333 | N29: 41665.521 | O29: 14 | P29: 36 | Q29: male | R29: monthly | S29: 41662 | T29: =IF(kiva_loans__muestra[[#This Row],[loan_amount]]>5000,"Alto","Bajo") -> Bajo | U29: =VLOOKUP(kiva_loans__muestra[[#This Row],[country]],Pais!A:B,2,FALSE) -> Rest of Europe | V29: 👨‍🦰M
A30: 661354 | B30: 1950 | C30: 1950 | D30: Clothing Sales | E30: Clothing | F30: to stock up on clothing inventory. | G30: AL | H30: Albania | I30: Elbasan | J30: ALL | K30: 2390 | L30: 41663.351 | M30: 41656.333 | N30: 41677.12 | O30: 26 | P30: 69 | Q30: male | R30: monthly | S30: 41663 | T30: =IF(kiva_loans__muestra[[#This Row],[loan_amount]]>5000,"Alto","Bajo") -> Bajo | U30: =VLOOKUP(kiva_loans__muestra[[#This Row],[country]],Pais!A:B,2,FALSE) -> Rest of Europe | V30: 👨‍🦰M
A31: 661360 | B31: 1950 | C31: 1950 | D31: Used Clothing | E31: Clothing | F31: to buy used clothes, shoes and electrical home appliances to sell. | G31: AL | H31: Albania | J31: ALL | K31: 2390 | L31: 41663.358 | M31: 41656.333 | N31: 41668.679 | O31: 26 | P31: 68 | Q31: female | R31: monthly | S31: 41663 | T31: =IF(kiva_loans__muestra[[#This Row],[loan_amount]]>5000,"Alto","Bajo") -> Bajo | U31: =VLOOKUP(kiva_loans__muestra[[#This Row],[country]],Pais!A:B,2,FALSE) -> Rest of Europe | V31: 👩 F
A32: 661387 | B32: 1950 | C32: 1950 | D32: Agriculture | E32: Agriculture | F32: to buy baby goats and sheep. | G32: AL | H32: Albania | I32: Elbasan | J32: ALL | K32: 2390 | L32: 41663.385 | M32: 41659.333 | N32: 41680.764 | O32: 26 | P32: 73 | Q32: male | R32: monthly | S32: 41663 | T32: =IF(kiva_loans__muestra[[#This Row],[loan_amount]]>5000,"Alto","Bajo") -> Bajo | U32: =VLOOKUP(kiva_loans__muestra[[#This Row],[country]],Pais!A:B,2,FALSE) -> Rest of Europe | V32: 👨‍🦰M
A33: 661404 | B33: 1475 | C33: 1475 | D33: Taxi | E33: Transportation | F33: to purchase a taxi vehicle for her husband. | G33: AL | H33: Albania | I33: Elbasan | J33: ALL | K33: 2390 | L33: 41663.401 | M33: 41656.333 | N33: 41672.9 | O33: 20 | P33: 52 | Q33: female | R33: monthly | S33: 41663 | T33: =IF(kiva_loans__muestra[[#This Row],[loan_amount]]>5000,"Alto","Bajo") -> Bajo | U33: =VLOOKUP(kiva_loans__muestra[[#This Row],[country]],Pais!A:B,2,FALSE) -> Rest of Europe | V33: 👩 F
A34: 661415 | B34: 975 | C34: 975 | D34: Agriculture | E34: Agriculture | F34: to buy a dairy cow. | G34: AL | H34: Albania | I34: Elbasan | J34: ALL | K34: 2390 | L34: 41663.412 | M34: 41661.333 | N34: 41664.638 | O34: 20 | P34: 33 | Q34: female | R34: monthly | S34: 41663 | T34: =IF(kiva_loans__muestra[[#This Row],[loan_amount]]>5000,"Alto","Bajo") -> Bajo | U34: =VLOOKUP(kiva_loans__muestra[[#This Row],[country]],Pais!A:B,2,FALSE) -> Rest of Europe | V34: 👩 F
A35: 661438 | B35: 975 | C35: 975 | D35: Farming | E35: Agriculture | F35: to buy potato seeds | G35: AL | H35: Albania | I35: Korce | J35: ALL | K35: 2390 | L35: 41663.446 | M35: 41661.333 | N35: 41665.918 | O35: 10 | P35: 35 | Q35: male | R35: bullet | S35: 41663 | T35: =IF(kiva_loans__muestra[[#This Row],[loan_amount]]>5000,"Alto","Bajo") -> Bajo | U35: =VLOOKUP(kiva_loans__muestra[[#This Row],[country]],Pais!A:B,2,FALSE) -> Rest of Europe | V35: 👨‍🦰M
A36: 661442 | B36: 975 | C36: 975 | D36: Agriculture | E36: Agriculture | F36: to buy onion seeds | G36: AL | H36: Albania | I36: Korce | J36: ALL | K36: 2390 | L36: 41663.455 | M36: 41660.333 | N36: 41664.656 | O36: 20 | P36: 37 | Q36: female | R36: monthly | S36: 41663 | T36: =IF(kiva_loans__muestra[[#This Row],[loan_amount]]>5000,"Alto","Bajo") -> Bajo | U36: =VLOOKUP(kiva_loans__muestra[[#This Row],[country]],Pais!A:B,2,FALSE) -> Rest of Europe | V36: 👩 F
A37: 661458 | B37: 1475 | C37: 1475 | D37: Dairy | E37: Agriculture | F37: add more cows to her existing herd. | G37: AL | H37: Albania | J37: ALL | K37: 2390 | L37: 41663.478 | M37: 41663.333 | N37: 41667.111 | O37: 26 | P37: 51 | Q37: female | R37: monthly | S37: 41663 | T37: =IF(kiva_loans__muestra[[#This Row],[loan_amount]]>5000,"Alto","Bajo") -> Bajo | U37: =VLOOKUP(kiva_loans__muestra[[#This Row],[country]],Pais!A:B,2,FALSE) -> Rest of Europe | V37: 👩 F
A38: 661543 | B38: 1475 | C38: 1475 | D38: Construction | E38: Construction | F38: to do some work at his newly built home that he will use for business as well | G38: AL | H38: Albania | I38: Elbasan | J38: ALL | K38: 2390 | L38: 41663.586 | M38: 41656.333 | N38: 41688.971 | O38: 20 | P38: 53 | Q38: female | R38: monthly | S38: 41663 | T38: =IF(kiva_loans__muestra[[#This Row],[loan_amount]]>5000,"Alto","Bajo") -> Bajo | U38: =VLOOKUP(kiva_loans__muestra[[#This Row],[country]],Pais!A:B,2,FALSE) -> Rest of Europe | V38: 👩 F
A39: 661544 | B39: 975 | C39: 975 | D39: Hardware | E39: Retail | F39: To stock up on construction materials for his hardware store | G39: AL | H39: Albania | J39: ALL | K39: 2390 | L39: 41663.589 | M39: 41663.333 | N39: 41672.725 | O39: 14 | P39: 33 | Q39: female | R39: monthly | S39: 41663 | T39: =IF(kiva_loans__muestra[[#This Row],[loan_amount]]>5000,"Alto","Bajo") -> Bajo | U39: =VLOOKUP(kiva_loans__muestra[[#This Row],[country]],Pais!A:B,2,FALSE) -> Rest of Europe | V39: 👩 F
A40: 661547 | B40: 500 | C40: 500 | D40: Farming | E40: Agriculture | F40: To buy seeds (potato and onion) for seasonal planting | G40: AL | H40: Albania | J40: ALL | K40: 2390 | L40: 41663.593 | M40: 41662.333 | N40: 41664.947 | O40: 13 | P40: 16 | Q40: male | R40: monthly | S40: 41663 | T40: =IF(kiva_loans__muestra[[#This Row],[loan_amount]]>5000,"Alto","Bajo") -> Bajo | U40: =VLOOKUP(kiva_loans__muestra[[#This Row],[country]],Pais!A:B,2,FALSE) -> Rest of Europe | V40: 👨‍🦰M
...

Sheet Dashboard

Sheet Pais
A1: Country | B1: Continente | C1: País o territorio
A2: =E2 -> Afganistan | B2: Asia | C2: AFGANISTAN | D2: =LOWER(C2) -> afganistan | E2: =PROPER(D2) -> Afganistan
A3: =E3 -> Albania | B3: Rest of Europe | C3: Albania | D3: =LOWER(C3) -> albania | E3: =PROPER(D3) -> Albania
A4: =E4 -> Alemania | B4: European Union | C4: ALEMANIA | D4: =LOWER(C4) -> alemania | E4: =PROPER(D4) -> Alemania
A5: =E5 -> Andorra | B5: Rest of Europe | C5: ANDORRA | D5: =LOWER(C5) -> andorra | E5: =PROPER(D5) -> Andorra
A6: =E6 -> Angola | B6: Africa | C6: ANGOLA | D6: =LOWER(C6) -> angola | E6: =PROPER(D6) -> Angola
A7: =E7 -> Anguilla | B7: Central America | C7: ANGUILLA | D7: =LOWER(C7) -> anguilla | E7: =PROPER(D7) -> Anguilla
A8: =E8 -> Antigua Y Barbuda | B8: Central America | C8: ANTIGUA Y BARBUDA | D8: =LOWER(C8) -> antigua y barbuda | E8: =PROPER(D8) -> Antigua Y Barbuda
A9: =E9 -> Antillas Holandesas | B9: Central America | C9: ANTILLAS HOLANDESAS | D9: =LOWER(C9) -> antillas holandesas | E9: =PROPER(D9) -> Antillas Holandesas
A10: =E10 -> Arabia Saudi | B10: Asia | C10: ARABIA SAUDI | D10: =LOWER(C10) -> arabia saudi | E10: =PROPER(D10) -> Arabia Saudi
A11: =E11 -> Argelia | B11: Africa | C11: ARGELIA | D11: =LOWER(C11) -> argelia | E11: =PROPER(D11) -> Argelia
A12: =E12 -> Argentina | B12: South America | C12: ARGENTINA | D12: =LOWER(C12) -> argentina | E12: =PROPER(D12) -> Argentina
A13: =E13 -> Armenia | B13: Rest of Europe | C13: Armenia | D13: =LOWER(C13) -> armenia | E13: =PROPER(D13) -> Armenia
... A250: =E250 -> Kosovo | B250: Rest of Europe | C250: Kosovo | D250: =LOWER(C250) -> kosovo | E250: =PROPER(D250) -> Kosovo
